Workbook

Sheet Resumen
A1: UdeSA-X · Entrega intermedia · Historias de usuario
A2: Estado al 2 de octubre de 2026. Fuente: backlog y pull requests de la organización tds-g6-2s2026 en GitHub.
A4: Puntos | B4: Total del backlog | C4: Hechos | D4: Hechos con la issue cerrada | E4: % hecho
A5: Obligatorias | B5: =SUMIF(Historias!$E:$E,"Obligatoria",Historias!$F:$F) | C5: =SUMIF(Historias!$E:$E,"Obligatoria",Historias!$O:$O) | D5: =SUMIFS(Historias!$F:$F,Historias!$E:$E,"Obligatoria",Historias!$M:$M,"Sí") | E5: =IF(B5=0,0,C5/B5)
A6: Optativas | B6: =SUMIF(Historias!$E:$E,"Optativa",Historias!$F:$F) | C6: =SUMIF(Historias!$E:$E,"Optativa",Historias!$O:$O) | D6: =SUMIFS(Historias!$F:$F,Historias!$E:$E,"Optativa",Historias!$M:$M,"Sí") | E6: =IF(B6=0,0,C6/B6)
A7: Total | B7: =B5+B6 | C7: =C5+C6 | D7: =D5+D6 | E7: =IF(B7=0,0,C7/B7)
A9: Referencia de la cátedra para la entrega intermedia | B9: 65
A10: Diferencia contra la referencia | B10: =C7-B9
A12: Por integrante | B12: Obligatorios hechos | C12: Optativos hechos | D12: Optativos requeridos al final | E12: Optativos que faltan
A13: Joaquín Szterensus | B13: =SUMIFS(Historias!$O:$O,Historias!$H:$H,A13,Historias!$E:$E,"Obligatoria") | C13: =SUMIFS(Historias!$O:$O,Historias!$H:$H,A13,Historias!$E:$E,"Optativa") | D13: 15 | E13: =MAX(0,D13-C13)
A14: Santino Domato | B14: =SUMIFS(Historias!$O:$O,Historias!$H:$H,A14,Historias!$E:$E,"Obligatoria") | C14: =SUMIFS(Historias!$O:$O,Historias!$H:$H,A14,Historias!$E:$E,"Optativa") | D14: 15 | E14: =MAX(0,D14-C14)
A15: Tomás Díaz | B15: =SUMIFS(Historias!$O:$O,Historias!$H:$H,A15,Historias!$E:$E,"Obligatoria") | C15: =SUMIFS(Historias!$O:$O,Historias!$H:$H,A15,Historias!$E:$E,"Optativa") | D15: 15 | E15: =MAX(0,D15-C15)
A16: Facundo Vulcano | B16: =SUMIFS(Historias!$O:$O,Historias!$H:$H,A16,Historias!$E:$E,"Obligatoria") | C16: =SUMIFS(Historias!$O:$O,Historias!$H:$H,A16,Historias!$E:$E,"Optativa") | D16: 15 | E16: =MAX(0,D16-C16)
A18: Cómo se cuenta: cada historia suma una sola vez, a nombre de su responsable (la persona asignada en GitHub). Quién hizo el backend y quién la app figura en la hoja Historias.
A19: Las issues 57 a 60 del backlog son la parte de app de historias que ya figuran (retweet, guardados, seguir y hashtags), por eso no se suman aparte.

Sheet Historias
A1: Épica | B1: Nombre de la épica | C1: Historia | D1: Título | E1: Tipo | F1: Puntos | G1: Estado | H1: Responsable | I1: Backend | J1: App mobile | K1: Pull requests | L1: Issue | M1: Issue cerrada | N1: Pendiente o aclaración | O1: Puntos hechos
A2: E.1 | B2: Usuarios | C2: H1 | D2: Registro de Usuarios | E2: Obligatoria | F2: 3 | G2: Hecha | H2: Joaquín Szterensus | I2: Joaquín Szterensus | J2: Joaquín Szterensus | K2: auth #1, #3, #14 · mobile #1 | L2: #1 | M2: Sí | N2: CA.6: la app no tiene el botón para reenviar el mail de verificación (el endpoint ya existe en auth). | O2: =IF(LEFT(G2,5)="Hecha",F2,0)
A3: E.1 | B3: Usuarios | C3: H2 | D3: Inicio de Sesión | E3: Obligatoria | F3: 3 | G3: Hecha | H3: Santino Domato | I3: Santino Domato | J3: Joaquín Szterensus | K3: auth #2, #8 | L3: #2 | M3: Sí | O3: =IF(LEFT(G3,5)="Hecha",F3,0)
A4: E.1 | B4: Usuarios | C4: H3 | D4: Cierre de Sesión | E4: Obligatoria | F4: 1 | G4: Hecha | H4: Joaquín Szterensus | I4: Joaquín Szterensus | J4: Joaquín Szterensus | K4: auth #9 · mobile #2 | L4: #3 | M4: Sí | O4: =IF(LEFT(G4,5)="Hecha",F4,0)
A5: E.1 | B5: Usuarios | C5: H4 | D5: Eliminación de Cuenta | E5: Obligatoria | F5: 3 | G5: Hecha | H5: Facundo Vulcano | I5: Facundo Vulcano | J5: Joaquín Szterensus | K5: auth #5 | L5: #4 | M5: Sí | N5: CA.2: los follows del usuario borrado siguen en social. CA.5: sus respuestas desaparecen del hilo en vez de mostrar "[Usuario eliminado]". Ambos dependen de la cola de eventos. | O5: =IF(LEFT(G5,5)="Hecha",F5,0)
A6: E.1 | B6: Usuarios | C6: H5 | D6: Olvidé Mi Contraseña | E6: Obligatoria | F6: 3 | G6: Hecha | H6: Tomás Díaz | I6: Tomás Díaz, Joaquín Szterensus | J6: Joaquín Szterensus | K6: auth #6, #7 · mobile #1 | L6: #5 | M6: Sí | O6: =IF(LEFT(G6,5)="Hecha",F6,0)
A7: E.1 | B7: Usuarios | C7: H6 | D7: Editar mi perfil | E7: Obligatoria | F7: 2 | G7: Hecha | H7: Facundo Vulcano | I7: Facundo Vulcano | J7: Joaquín Szterensus | K7: auth #11 | L7: #6 | M7: Sí | O7: =IF(LEFT(G7,5)="Hecha",F7,0)
A8: E.1 | B8: Usuarios | C8: H7 | D8: Preferencias | E8: Optativa | F8: 2 | G8: Hecha | H8: Tomás Díaz | I8: Tomás Díaz | J8: Tomás Díaz, Joaquín Szterensus | K8: auth #13 | L8: #7 | M8: Sí | O8: =IF(LEFT(G8,5)="Hecha",F8,0)
A9: E.1 | B9: Usuarios | C9: H8 | D9: Foto de Perfil | E9: Optativa | F9: 3 | G9: Asignada | H9: Tomás Díaz | L9: #8 | M9: No | O9: =IF(LEFT(G9,5)="Hecha",F9,0)
A10: E.1 | B10: Usuarios | C10: H9 | D10: Social Login | E10: Optativa | F10: 5 | G10: Sin asignar | L10: #9 | M10: No | O10: =IF(LEFT(G10,5)="Hecha",F10,0)
A11: E.1 | B11: Usuarios | C11: H10 | D11: Tema de la Aplicación | E11: Optativa | F11: 1 | G11: Hecha | H11: Tomás Díaz | J11: Tomás Díaz | K11: mobile #5 | L11: #10 | M11: Sí | O11: =IF(LEFT(G11,5)="Hecha",F11,0)
A12: E.1 | B12: Usuarios | C12: H11 | D12: Enviar Feedback o Reportar Error | E12: Optativa | F12: 3 | G12: Sin asignar | L12: #11 | M12: No | O12: =IF(LEFT(G12,5)="Hecha",F12,0)
A13: E.1 | B13: Usuarios | C13: H12 | D13: Aceptación de Términos y Política de Privacidad | E13: Obligatoria | F13: 1 | G13: Hecha | H13: Facundo Vulcano | I13: Facundo Vulcano | J13: Joaquín Szterensus | K13: auth #12 | L13: #12 | M13: Sí | N13: CA.1: el checkbox del registro no tiene links a los textos y el botón no se deshabilita. | O13: =IF(LEFT(G13,5)="Hecha",F13,0)
A14: E.1 | B14: Usuarios | C14: H13 | D14: Cambiar Contraseña | E14: Optativa | F14: 3 | G14: Hecha | H14: Santino Domato | I14: Santino Domato | J14: Joaquín Szterensus | K14: auth #10 | L14: #13 | M14: Sí | O14: =IF(LEFT(G14,5)="Hecha",F14,0)
A15: E.1 | B15: Usuarios | C15: H14 | D15: Onboarding Inicial | E15: Optativa | F15: 3 | G15: Sin asignar | L15: #14 | M15: No | O15: =IF(LEFT(G15,5)="Hecha",F15,0)
A16: E.2 | B16: Publicaciones | C16: H1 | D16: Crear Post (Tweet) | E16: Obligatoria | F16: 3 | G16: Hecha | H16: Joaquín Szterensus | I16: Joaquín Szterensus | J16: Joaquín Szterensus | K16: posts #1 | L16: #15 | M16: Sí | O16: =IF(LEFT(G16,5)="Hecha",F16,0)
A17: E.2 | B17: Publicaciones | C17: H2 | D17: Feed Principal (Timeline) | E17: Obligatoria | F17: 3 | G17: Hecha | H17: Santino Domato | I17: Santino Domato (posts, auth, social) | J17: Santino Domato | K17: posts #12 · auth #18 · social #2 · mobile #8 | L17: #16 | M17: Sí | N17: La issue no tiene responsable asignado en GitHub. | O17: =IF(LEFT(G17,5)="Hecha",F17,0)
A18: E.2 | B18: Publicaciones | C18: H3 | D18: Eliminar Post | E18: Obligatoria | F18: 2 | G18: Hecha | H18: Santino Domato | I18: Santino Domato | J18: Santino Domato | K18: posts #3, #9 · mobile #6 | L18: #17 | M18: Sí | O18: =IF(LEFT(G18,5)="Hecha",F18,0)
A19: E.2 | B19: Publicaciones | C19: H4 | D19: Responder a un Post | E19: Obligatoria | F19: 2 | G19: Hecha (falta cerrar la issue) | H19: Joaquín Szterensus | I19: Joaquín Szterensus | J19: Joaquín Szterensus | K19: posts #5 · mobile #4 | L19: #18 | M19: No | N19: Implementada y mergeada; falta cerrar la issue. | O19: =IF(LEFT(G19,5)="Hecha",F19,0)
A20: E.2 | B20: Publicaciones | C20: H5 | D20: Retweet / Repost | E20: Obligatoria | F20: 2 | G20: Hecha (falta cerrar la issue) | H20: Santino Domato | I20: Santino Domato, Facundo Vulcano | J20: Facundo Vulcano | K20: posts #3, #14, #16 · mobile #9, #13 | L20: #19 | M20: No | N20: Implementada y mergeada; falta cerrar la issue. CA.3 pide que el retweet desaparezca del perfil, pero la pantalla de perfil (E.2 H14) no existe todavía. | O20: =IF(LEFT(G20,5)="Hecha",F20,0)
A21: E.2 | B21: Publicaciones | C21: H6 | D21: Like a un Post | E21: Obligatoria | F21: 2 | G21: Hecha | H21: Joaquín Szterensus | I21: Joaquín Szterensus | J21: Joaquín Szterensus | K21: posts #4 · mobile #3 | L21: #20 | M21: Sí | O21: =IF(LEFT(G21,5)="Hecha",F21,0)
A22: E.2 | B22: Publicaciones | C22: H7 | D22: Post con Imagen | E22: Obligatoria | F22: 5 | G22: En curso | H22: Tomás Díaz | I22: Tomás Díaz | J22: Tomás Díaz | K22: posts #10 · media #1 · mobile #7 (abiertos) | L22: #21 | M22: No | N22: En curso: pull requests abiertos. | O22: =IF(LEFT(G22,5)="Hecha",F22,0)
A23: E.2 | B23: Publicaciones | C23: H8 | D23: Hashtags | E23: Optativa | F23: 3 | G23: Hecha | H23: Facundo Vulcano | I23: Facundo Vulcano | J23: Facundo Vulcano | K23: posts #11 · mobile #11 | L23: #22 | M23: Sí | O23: =IF(LEFT(G23,5)="Hecha",F23,0)
A24: E.2 | B24: Publicaciones | C24: H9 | D24: Menciones a Usuarios | E24: Optativa | F24: 3 | G24: Sin asignar | L24: #23 | M24: No | O24: =IF(LEFT(G24,5)="Hecha",F24,0)
A25: E.2 | B25: Publicaciones | C25: H10 | D25: Búsqueda de Posts y Usuarios | E25: Obligatoria | F25: 5 | G25: Sin asignar | L25: #24 | M25: No | O25: =IF(LEFT(G25,5)="Hecha",F25,0)
A26: E.2 | B26: Publicaciones | C26: H11 | D26: Trending Topics | E26: Optativa | F26: 3 | G26: Asignada | H26: Facundo Vulcano | L26: #25 | M26: No | O26: =IF(LEFT(G26,5)="Hecha",F26,0)
A27: E.2 | B27: Publicaciones | C27: H12 | D27: Guardar Posts (Bookmarks) | E27: Optativa | F27: 3 | G27: Hecha | H27: Facundo Vulcano | I27: Facundo Vulcano | J27: Facundo Vulcano | K27: posts #6 · mobile #10, #13 | L27: #26 | M27: Sí | O27: =IF(LEFT(G27,5)="Hecha",F27,0)
A28: E.2 | B28: Publicaciones | C28: H13 | D28: Citar Post (Quote Tweet) | E28: Optativa | F28: 5 | G28: Sin asignar | L28: #27 | M28: No | O28: =IF(LEFT(G28,5)="Hecha",F28,0)
A29: E.2 | B29: Publicaciones | C29: H14 | D29: Visualización de Perfil de Usuario | E29: Obligatoria | F29: 3 | G29: Sin asignar | L29: #28 | M29: No | O29: =IF(LEFT(G29,5)="Hecha",F29,0)
A30: E.2 | B30: Publicaciones | C30: H15 | D30: Post con Video | E30: Optativa | F30: 5 | G30: Sin asignar | L30: #29 | M30: No | O30: =IF(LEFT(G30,5)="Hecha",F30,0)
A31: E.3 | B31: Interacciones sociales | C31: H1 | D31: Seguir a un Usuario | E31: Obligatoria | F31: 5 | G31: Hecha | H31: Joaquín Szterensus | I31: Joaquín Szterensus (social, auth) | J31: Tomás Díaz | K31: social #1 · auth #17 · mobile #14, #15 | L31: #30 | M31: Sí | O31: =IF(LEFT(G31,5)="Hecha",F31,0)
A32: E.3 | B32: Interacciones sociales | C32: H2 | D32: Dejar de Seguir a un Usuario | E32: Obligatoria | F32: 2 | G32: Sin asignar | L32: #31 | M32: No | O32: =IF(LEFT(G32,5)="Hecha",F32,0)
A33: E.3 | B33: Interacciones sociales | C33: H3 | D33: Listado de Seguidores y Seguidos | E33: Obligatoria | F33: 3 | G33: Sin asignar | L33: #32 | M33: No | O33: =IF(LEFT(G33,5)="Hecha",F33,0)
A34: E.3 | B34: Interacciones sociales | C34: H4 | D34: Bloquear Usuario | E34: Obligatoria | F34: 2 | G34: Sin asignar | L34: #33 | M34: No | O34: =IF(LEFT(G34,5)="Hecha",F34,0)
A35: E.3 | B35: Interacciones sociales | C35: H5 | D35: Denunciar Usuario | E35: Obligatoria | F35: 2 | G35: Sin asignar | L35: #34 | M35: No | O35: =IF(LEFT(G35,5)="Hecha",F35,0)
A36: E.3 | B36: Interacciones sociales | C36: H6 | D36: Mensajes Directos (DM) | E36: Optativa | F36: 8 | G36: Sin asignar | L36: #35 | M36: No | O36: =IF(LEFT(G36,5)="Hecha",F36,0)
A37: E.3 | B37: Interacciones sociales | C37: H7 | D37: Usuarios en línea | E37: Optativa | F37: 3 | G37: Sin asignar | L37: #36 | M37: No | O37: =IF(LEFT(G37,5)="Hecha",F37,0)
A38: E.3 | B38: Interacciones sociales | C38: H8 | D38: Listas Personalizadas | E38: Optativa | F38: 3 | G38: Sin asignar | L38: #37 | M38: No | O38: =IF(LEFT(G38,5)="Hecha",F38,0)
A39: E.3 | B39: Interacciones sociales | C39: H9 | D39: Invitar Usuarios Externos | E39: Optativa | F39: 2 | G39: Sin asignar | L39: #38 | M39: No | O39: =IF(LEFT(G39,5)="Hecha",F39,0)
A40: E.3 | B40: Interacciones sociales | C40: H10 | D40: Silenciar Usuario | E40: Optativa | F40: 5 | G40: Sin asignar | L40: #39 | M40: No | O40: =IF(LEFT(G40,5)="Hecha",F40,0)
...

Sheet Requisitos técnicos
A1: Requisito del enunciado | B1: Estado | C1: Responsable | D1: Evidencia o aclaración
A2: App principal exclusivamente mobile | B2: Cumplido | C2: Joaquín Szterensus (base), todo el equipo | D2: mobile-app: React Native con Expo y TypeScript.
A3: Backoffice web para administradores | B3: En curso | C3: Santino Domato, Tomás Díaz | D3: admin-service sirve el portal web (admin #6 mergeado; #9 abierto).
A4: Arquitectura de microservicios | B4: Cumplido | C4: Equipo | D4: auth, posts, social, media y admin, más un api-gateway.
A5: Al menos dos tipos de base de datos | B5: Cumplido | C5: Equipo | D5: PostgreSQL, una base por servicio, y Redis para datos con vencimiento.
A6: Backend en más de una tecnología | B6: Cumplido | C6: Joaquín Szterensus, Santino Domato, Tomás Díaz | D6: admin-service está escrito en Go; el resto, en Python con FastAPI.
A7: Desplegada en la nube, cada servicio en Docker | B7: En curso | C7: Joaquín Szterensus | D7: Dockerfile en cada servicio. Manifiestos de Kubernetes para EKS mergeados el 02/10; auth ya desplegado, el resto falla en el último despliegue.
A8: Seguridad según OWASP Top 10 | B8: Parcial | C8: Equipo | D8: Argon2id, JWT firmados y revocables, bloqueo por intentos, rate limiting, sanitización y secretos por GitHub Secrets. Falta impedir el secreto JWT por defecto en producción y activar Dependabot.
A9: Metodología ágil y herramientas de seguimiento | B9: Cumplido | C9: Equipo | D9: Sprints semanales, GitHub Project, issues con etiquetas de épica, puntos y servicio, y pull requests con review.
A10: Documentación técnica y funcional | B10: En curso | C10: Equipo | D10: README y guía de contribución por repo; ADRs y diagramas de esta entrega.
A11: Tests unitarios, de integración y de estrés | B11: Parcial | C11: Equipo | D11: Unitarios e integración en todos los backends. Pruebas de estrés pendientes.
A12: Tests de integración en todos los backends | B12: Cumplido | C12: Equipo | D12: Corren contra un PostgreSQL real en la CI de cada servicio.
... A15: Despliegue continuo con GitHub Actions | B15: En curso | C15: Joaquín Szterensus | D15: Workflow de deploy en los 6 servicios: OIDC, imagen en ECR, aplicar en EKS y esperar el rollout.
A16: Observabilidad: métricas, logs y trazas, con acceso del tutor | B16: Pendiente | D16: Todavía no implementado.
A17: Rate limiting en al menos un microservicio | B17: Cumplido | C17: Joaquín Szterensus, Santino Domato | D17: posts: 30 posts por hora. social: 50 follows por hora. auth: bloqueo tras 5 intentos de login fallidos.
A18: Al menos una cola asincrónica entre dos microservicios | B18: Pendiente | D18: auth ya publica el evento user_deleted a través de una interfaz, hoy solo registrado en el log; falta el broker y el consumidor.
A19: Buena experiencia de usuario en app y backoffice | B19: En curso | C19: Equipo | D19: Sistema de diseño propio, tema claro y oscuro, idiomas español e inglés.
A20: Al menos una funcionalidad con inteligencia artificial | B20: Pendiente | D20: Se propone en la semana 11, acordada con el tutor.
